Workbook

Sheet NE
E7: NO AGREGAR PESTANAS NUEVAS ANTES DE VMI+BOOST INT

Sheet General
A2: Constraint | B2: Unidad | C2: Unidad | E2: Protocolo de Imagenes
A3: V(D)>V_% | B3: cGy | C3: % | E3: Tg interno + Tg externo - Semanal
A4: V(D)<V_% | B4: cGy | C4: cGy | E4: Tg interno + Tg externo - Diario
A5: Dmedia | B5: cGy | E5: Tg interno + Tg externo + Ant boost - Semanal
A6: Dmax | B6: cGy | E6: Tg interno + Tg externo - Semanal + Setup Boost
A7: V(D)<V_cc | B7: cGy | C7: cc | E7: Portales ANT-LAT diario
A8: D(V_%)<D | B8: % | C8: cGy | E8: Portales ANT-LAT día por medio
A9: D(V_%)>D | B9: % | C9: cGy | E9: Portales ANT-LAT semanal
A10: D(V_cc)<D | B10: cc | C10: cGy | E10: Portales POST-LAT diario
A11: D(V_cc)>D | B11: cc | C11: cGy | E11: Portales POST-LAT día por medio
E12: Portales POST-LAT semanal
E13: Definir previo a setup
E14: CBCT diario + CBCT primeros 3 días representativos para promedios
E15: CBCT día por medio + CBCT primeros 3 días representativos para promedios
E16: CBCT una vez por semana + CBCT primeros 3 días representativos para promedios
E17: CBCT dos veces por semana + CBCT primeros 3 días representativos para promedios
E18: CBCT primer día (Syn) + Tg interno segundo día en (Plat). Semanal
E19: CBCT primer día + CBCT semanal o 2 veces por semana sujeto a setup
E20: CBCT diario + Symmetry
E21: CBCT primer día (Syn) + Portales POST-LAT dia por medio
E22: CBCT diario (SRS/SBRT)

Sheet TEMPLATE COPIAR AL FINAL
A2: Prescripción: | B2: TEMPLATE COPIAR AL FINAL | D2: =IF($B$2=RIGHT(CELL("filename",$B$2),LEN(CELL("filename",$B$2))-FIND("]",CELL("filename",$B$2))), "Todo OK ", "No coincide nombre del template con nombre de Prescripción") -> Todo OK
A4: Estructura | B4: Dosis total (cGy) | C4: Dosis diaria (cGy) | D4: Nro de fx | E4: Nro de etapa | G4: Protocolo Imágenes
A5: PTV_VMI | B5: 4005 | C5: 267 | D5: ='TEMPLATE COPIAR AL FINAL'!$B5/'TEMPLATE COPIAR AL FINAL'!$C5 -> 15 | E5: 1
A7: Tipo de Estructura | B7: Estructura | C7: Tipo de Constraint | D7: Ideal | E7: Valor ref aux (dvh) | F7: Aceptable | G7: Valor ref limite aceptable aux (dvh)
A8: target | B8: PTV_VMI | D8: 3885 | E8: 95 | F8: 3805 | G8: 95
D9: 4800 | E9: 35
A46: ESTA LINEA TIENE QUE SER LA 46. Hardcodeado hasta este valor de fila. RL

Sheet VMI
A2: Prescripción: | B2: VMI | D2: =IF($B$2=RIGHT(CELL("filename",$B$2),LEN(CELL("filename",$B$2))-FIND("]",CELL("filename",$B$2))), "Todo OK ", "No coincide nombre del template con nombre de Prescripción") -> Todo OK
A4: Estructura | B4: Dosis total (cGy) | C4: Dosis diaria (cGy) | D4: Nro de fx | E4: Nro de etapa | G4: Protocolo Imágenes
A5: PTV_VMI | B5: 4005 | C5: 267 | D5: =VMI!$B5/VMI!$C5 -> 15 | E5: 1 | G5: Tg interno + Tg externo - Semanal
A7: Tipo de Estructura | B7: Estructura | C7: Tipo de Constraint | D7: Ideal | E7: Valor ref aux (dvh) | F7: Aceptable | G7: Valor ref limite aceptable aux (dvh)
A8: target | B8: PTV_VMI | C8: V(D)>V_% | D8: 3885 | E8: 95 | F8: 3805 | G8: 95
C9: Dmax | D9: 4285
A10: oar | B10: Mama_der | C10: Dmax | D10: 240 | F10: 384
C11: V(D)<V_% | D11: 144 | E11: 5 | F11: 240 | G11: 5
B12: Pulmon_I | C12: V(D)<V_% | D12: 1200 | E12: 15 | F12: 1200 | G12: 20
C13: V(D)<V_% | D13: 800 | E13: 30 | F13: 800 | G13: 35
C14: V(D)<V_% | D14: 400 | E14: 40 | F14: 400 | G14: 55
B15: Pulmon_D | C15: V(D)<V_% | D15: 400 | E15: 10
B16: Corazon | C16: V(D)<V_% | D16: 1600 | E16: 5
C17: V(D)<V_% | D17: 800 | E17: 30
C18: Dmedia | D18: 320 | F18: 400
B19: Paciente | C19: Dmax | D19: 4285
A46: Si es necesario agregar mas lineas de constraints, revisar el codigo. Hardcodeado hasta este valor de fila. RL

Sheet VMD
A2: Prescripción: | B2: VMD | D2: =IF($B$2=RIGHT(CELL("filename",$B$2),LEN(CELL("filename",$B$2))-FIND("]",CELL("filename",$B$2))), "Todo OK ", "No coincide nombre del template con nombre de Prescripción") -> Todo OK
A4: Estructura | B4: Dosis total (cGy) | C4: Dosis diaria (cGy) | D4: Nro de fx | E4: Nro de etapa | G4: Protocolo Imágenes
A5: PTV_VMD | B5: 4005 | C5: 267 | D5: =VMD!$B5/VMD!$C5 -> 15 | E5: 1 | G5: Tg interno + Tg externo - Semanal
A7: Tipo de Estructura | B7: Estructura | C7: Tipo de Constraint | D7: Ideal | E7: Valor ref aux (dvh) | F7: Aceptable | G7: Valor ref limite aceptable aux (dvh)
A8: target | B8: PTV_VMD | C8: V(D)>V_% | D8: 3885 | E8: 95 | F8: 3805 | G8: 95
C9: Dmax | D9: 4285
A10: oar | B10: Mama_I | C10: Dmax | D10: 240 | F10: 384
C11: V(D)<V_% | D11: 144 | E11: 5 | F11: 240 | G11: 5
B12: Pulmon_D | C12: V(D)<V_% | D12: 1200 | E12: 15 | F12: 1200 | G12: 20
C13: V(D)<V_% | D13: 800 | E13: 30 | F13: 800 | G13: 35
C14: V(D)<V_% | D14: 400 | E14: 40 | F14: 400 | G14: 55
B15: Pulmon_I | C15: V(D)<V_% | D15: 400 | E15: 10
B16: Corazon | C16: V(D)<V_% | D16: 1600 | E16: 5
C17: V(D)<V_% | D17: 800 | E17: 30
C18: Dmedia | D18: 320 | F18: 400
B19: Higado | C19: V(D)<V_% | D19: 1500 | E19: 3
C20: Dmedia | D20: 500
B21: Paciente | C21: Dmax | D21: 4285
A46: Si es necesario agregar mas lineas de constraints, revisar el codigo. Hardcodeado hasta este valor de fila. RL

Sheet VMI HIPO
A2: Prescripción: | B2: VMI HIPO | D2: =IF($B$2=RIGHT(CELL("filename",$B$2),LEN(CELL("filename",$B$2))-FIND("]",CELL("filename",$B$2))), "Todo OK ", "No coincide nombre del template con nombre de Prescripción") -> Todo OK
A4: Estructura | B4: Dosis total (cGy) | C4: Dosis diaria (cGy) | D4: Nro de fx | E4: Nro de etapa | G4: Protocolo Imágenes
A5: PTV_VMI | B5: 2600 | C5: 520 | D5: ='VMI HIPO'!$B5/'VMI HIPO'!$C5 -> 5 | E5: 1 | G5: Tg interno + Tg externo - Diario
A7: Tipo de Estructura | B7: Estructura | C7: Tipo de Constraint | D7: Ideal | E7: Valor ref aux (dvh) | F7: Aceptable | G7: Valor ref limite aceptable aux (dvh)
A8: target | B8: PTV_VMI | C8: V(D)>V_% | D8: 2522 | E8: 95 | F8: 2470 | G8: 95
C9: V(D)<V_% | D9: 2730 | E9: 2 | F9: 2782 | G9: 2
A10: oar | B10: Mama_D | C10: Dmax | D10: 600
C11: Dmedia | D11: 150
B12: Pulmon_I | C12: V(D)<V_% | D12: 800 | E12: 15
C13: V(D)<V_% | D13: 500 | E13: 30
C14: Dmedia | D14: 450
B15: Pulmon_D | C15: Dmedia | D15: 120 | F15: 580
C16: Dmax | D16: 700
B17: Corazon | C17: V(D)<V_% | D17: 700 | E17: 5
C18: V(D)<V_% | D18: 150 | E18: 30
C19: Dmedia | D19: 200 | F19: 300
B20: Medula | C20: Dmax | D20: 250 | F20: 400
B21: Paciente | C21: Dmax | D21: 2860
A47: Si es necesario agregar mas lineas de constraints, revisar el codigo. Hardcodeado hasta este valor de fila. RL

Sheet VMD HIPO
A2: Prescripción: | B2: VMD HIPO | D2: =IF($B$2=RIGHT(CELL("filename",$B$2),LEN(CELL("filename",$B$2))-FIND("]",CELL("filename",$B$2))), "Todo OK ", "No coincide nombre del template con nombre de Prescripción") -> Todo OK
A4: Estructura | B4: Dosis total (cGy) | C4: Dosis diaria (cGy) | D4: Nro de fx | E4: Nro de etapa | G4: Protocolo Imágenes
A5: PTV_VMD | B5: 2600 | C5: 520 | D5: ='VMD HIPO'!$B5/'VMD HIPO'!$C5 -> 5 | E5: 1 | G5: Tg interno + Tg externo - Diario
A7: Tipo de Estructura | B7: Estructura | C7: Tipo de Constraint | D7: Ideal | E7: Valor ref aux (dvh) | F7: Aceptable | G7: Valor ref limite aceptable aux (dvh)
A8: target | B8: PTV_VMD | C8: V(D)>V_% | D8: 2522 | E8: 95 | F8: 2470 | G8: 95
C9: V(D)<V_% | D9: 2730 | E9: 2 | F9: 2782 | G9: 2
A10: oar | B10: Mama_I | C10: Dmax | D10: 600
C11: Dmedia | D11: 150
B12: Pulmon_D | C12: V(D)<V_% | D12: 800 | E12: 15
C13: V(D)<V_% | D13: 500 | E13: 30
C14: Dmedia | D14: 450
B15: Pulmon_I | C15: Dmedia | D15: 120 | F15: 580
C16: Dmax | D16: 700
B17: Corazon | C17: V(D)<V_% | D17: 700 | E17: 5
C18: V(D)<V_% | D18: 150 | E18: 30
C19: Dmedia | D19: 200 | F19: 300
B20: Medula | C20: Dmax | D20: 250 | F20: 400
B21: Higado | C21: V(D)<V_% | D21: 1860 | E21: 60
B22: Paciente | C22: Dmax | D22: 2860
A47: Si es necesario agregar mas lineas de constraints, revisar el codigo. Hardcodeado hasta este valor de fila. RL

Sheet VMI+BOOST INT HIPO
A2: Prescripción: | B2: VMI+BOOST INT HIPO | D2: =IF($B$2=RIGHT(CELL("filename",$B$2),LEN(CELL("filename",$B$2))-FIND("]",CELL("filename",$B$2))), "Todo OK ", "No coincide nombre del template con nombre de Prescripción") -> Todo OK
A4: Estructura | B4: Dosis total (cGy) | C4: Dosis diaria (cGy) | D4: Nro de fx | E4: Nro de etapa | G4: Protocolo Imágenes
A5: PTV_VMI | B5: 2600 | C5: 520 | D5: ='VMI+BOOST INT HIPO'!$B5/'VMI+BOOST INT HIPO'!$C5 -> 5 | E5: 1 | G5: Tg interno + Tg externo - Diario
A6: PTV_BOOST | B6: 2900 | C6: 580 | D6: 5 | E6: 1
A8: Tipo de Estructura | B8: Estructura | C8: Tipo de Constraint | D8: Ideal | E8: Valor ref aux (dvh) | F8: Aceptable | G8: Valor ref limite aceptable aux (dvh)
A9: target | B9: PTV_VMI | C9: V(D)>V_% | D9: 2522 | E9: 95 | F9: 2470 | G9: 95
C10: V(D)<V_% | D10: 2900 | E10: 35
C11: V(D)<V_% | D11: 2730 | E11: 50
B12: PTV_LUMP | C12: V(D)>V_% | D12: 2813 | E12: 95
C13: Dmax | D13: 3103
A14: oar | B14: Mama_D | C14: Dmax | D14: 600
C15: Dmedia | D15: 150
B16: Pulmon_I | C16: V(D)<V_% | D16: 800 | E16: 15
C17: V(D)<V_% | D17: 500 | E17: 30
C18: Dmedia | D18: 450
B19: Pulmon_D | C19: Dmedia | D19: 120 | F19: 580
C20: Dmax | D20: 700
B21: Corazon | C21: V(D)<V_% | D21: 700 | E21: 5
C22: V(D)<V_% | D22: 150 | E22: 30
C23: Dmedia | D23: 200 | F23: 300
B24: Medula | C24: Dmax | D24: 250 | F24: 400
B25: Paciente | C25: Dmax | D25: 3103
A46: Si es necesario agregar mas lineas de constraints, revisar el codigo. Hardcodeado hasta este valor de fila. RL

Sheet VMD+BOOST INT HIPO
A2: Prescripción: | B2: VMD+BOOST INT HIPO | D2: =IF($B$2=RIGHT(CELL("filename",$B$2),LEN(CELL("filename",$B$2))-FIND("]",CELL("filename",$B$2))), "Todo OK ", "No coincide nombre del template con nombre de Prescripción") -> Todo OK
A4: Estructura | B4: Dosis total (cGy) | C4: Dosis diaria (cGy) | D4: Nro de fx | E4: Nro de etapa | G4: Protocolo Imágenes
A5: PTV_VMD | B5: 2600 | C5: 520 | D5: ='VMD+BOOST INT HIPO'!$B5/'VMD+BOOST INT HIPO'!$C5 -> 5 | E5: 1 | G5: Tg interno + Tg externo - Diario
A6: PTV_BOOST | B6: 2900 | C6: 580 | D6: 5 | E6: 1
A8: Tipo de Estructura | B8: Estructura | C8: Tipo de Constraint | D8: Ideal | E8: Valor ref aux (dvh) | F8: Aceptable | G8: Valor ref limite aceptable aux (dvh)
A9: target | B9: PTV_VMD | C9: V(D)>V_% | D9: 2522 | E9: 95 | F9: 2470 | G9: 95
C10: V(D)<V_% | D10: 2900 | E10: 35
C11: V(D)<V_% | D11: 2730 | E11: 50
B12: PTV_LUMP | C12: V(D)>V_% | D12: 2813 | E12: 95
C13: Dmax | D13: 3103
A14: oar | B14: Mama_I | C14: Dmax | D14: 600
C15: Dmedia | D15: 150
B16: Pulmon_D | C16: V(D)<V_% | D16: 800 | E16: 15
C17: V(D)<V_% | D17: 500 | E17: 30
C18: Dmedia | D18: 450
B19: Pulmon_I | C19: Dmedia | D19: 120 | F19: 580
C20: Dmax | D20: 700
B21: Corazon | C21: V(D)<V_% | D21: 700 | E21: 5
C22: V(D)<V_% | D22: 150 | E22: 30
C23: Dmedia | D23: 200 | F23: 300
B24: Medula | C24: Dmax | D24: 250 | F24: 400
B25: Higado | C25: V(D)<V_% | D25: 1860 | E25: 60
B26: Paciente | C26: Dmax | D26: 3103
A46: Si es necesario agregar mas lineas de constraints, revisar el codigo. Hardcodeado hasta este valor de fila. RL

Sheet VMI+BOOST INT
A2: Prescripción: | B2: VMI+BOOST INT | D2: =IF($B$2=RIGHT(CELL("filename",$B$2),LEN(CELL("filename",$B$2))-FIND("]",CELL("filename",$B$2))), "Todo OK ", "No coincide nombre del template con nombre de Prescripción") -> Todo OK
A4: Estructura | B4: Dosis total (cGy) | C4: Dosis diaria (cGy) | D4: Nro de fx | E4: Nro de etapa | G4: Protocolo Imágenes
A5: PTV_VMI | B5: 4005 | C5: 267 | D5: ='VMI+BOOST INT'!$B5/'VMI+BOOST INT'!$C5 -> 15 | E5: 1 | G5: Tg interno + Tg externo + Ant boost - Semanal
A6: PTV_BOOST | B6: 4800 | C6: 320 | D6: ='VMI+BOOST INT'!$B6/'VMI+BOOST INT'!$C6 -> 15 | E6: 1
A8: Tipo de Estructura | B8: Estructura | C8: Tipo de Constraint | D8: Ideal | E8: Valor ref aux (dvh) | F8: Aceptable | G8: Valor ref limite aceptable aux (dvh)
A9: target | B9: PTV_VMI | C9: V(D)>V_% | D9: 3885 | E9: 95 | F9: 3805 | G9: 95
C10: V(D)<V_% | D10: 4800 | E10: 35
C11: V(D)<V_% | D11: 4320 | E11: 50
B12: PTV_BOOST | C12: V(D)>V_% | D12: 4656 | E12: 95
C13: V(D)<V_% | D13: 5280 | E13: 5
C14: Dmax | D14: 5376
A15: oar | B15: Mama_der | C15: Dmax | D15: 240 | F15: 384
C16: V(D)<V_% | D16: 144 | E16: 5 | F16: 240 | G16: 5
B17: Pulmon_I | C17: V(D)<V_% | D17: 1200 | E17: 15 | F17: 1200 | G17: 20
C18: V(D)<V_% | D18: 800 | E18: 30 | F18: 800 | G18: 35
C19: V(D)<V_% | D19: 400 | E19: 40 | F19: 400 | G19: 55
B20: Pulmon_D | C20: V(D)<V_% | D20: 400 | E20: 10
B21: Corazon | C21: V(D)<V_% | D21: 1600 | E21: 5
C22: V(D)<V_% | D22: 800 | E22: 30
C23: Dmedia | D23: 320 | F23: 400
B24: Paciente | C24: Dmax | D24: 5136
A46: Si es necesario agregar mas lineas de constraints, revisar el codigo. Hardcodeado hasta este valor de fila. RL

Sheet VMD+BOOST INT
A2: Prescripción: | B2: VMD+BOOST INT | D2: =IF($B$2=RIGHT(CELL("filename",$B$2),LEN(CELL("filename",$B$2))-FIND("]",CELL("filename",$B$2))), "Todo OK ", "No coincide nombre del template con nombre de Prescripción") -> Todo OK
A4: Estructura | B4: Dosis total (cGy) | C4: Dosis diaria (cGy) | D4: Nro de fx | E4: Nro de etapa | G4: Protocolo Imágenes
A5: PTV_VMD | B5: 4005 | C5: 267 | D5: ='VMD+BOOST INT'!$B5/'VMD+BOOST INT'!$C5 -> 15 | E5: 1 | G5: Tg interno + Tg externo + Ant boost - Semanal
A6: PTV_BOOST | B6: 4800 | C6: 320 | D6: ='VMD+BOOST INT'!$B6/'VMD+BOOST INT'!$C6 -> 15 | E6: 1
A8: Tipo de Estructura | B8: Estructura | C8: Tipo de Constraint | D8: Ideal | E8: Valor ref aux (dvh) | F8: Aceptable | G8: Valor ref limite aceptable aux (dvh)
A9: target | B9: PTV_VMD | C9: V(D)>V_% | D9: 3885 | E9: 95 | F9: 3805 | G9: 95
C10: V(D)<V_% | D10: 4800 | E10: 35
C11: V(D)<V_% | D11: 4320 | E11: 50
B12: PTV_BOOST | C12: V(D)>V_% | D12: 4656 | E12: 95
C13: V(D)<V_% | D13: 5280 | E13: 5
C14: Dmax | D14: 5376
A15: oar | B15: Mama_I | C15: Dmax | D15: 240 | F15: 384
C16: V(D)<V_% | D16: 144 | E16: 5 | F16: 240 | G16: 5
B17: Pulmon_D | C17: V(D)<V_% | D17: 1200 | E17: 15 | F17: 1200 | G17: 20
C18: V(D)<V_% | D18: 800 | E18: 30 | F18: 800 | G18: 35
C19: V(D)<V_% | D19: 400 | E19: 40 | F19: 400 | G19: 55
B20: Pulmon_I | C20: V(D)<V_% | D20: 400 | E20: 10
B21: Corazon | C21: V(D)<V_% | D21: 1600 | E21: 5
C22: V(D)<V_% | D22: 800 | E22: 30
C23: Dmedia | D23: 320 | F23: 400
B24: Higado | C24: V(D)<V_% | D24: 1500 | E24: 3
C25: Dmedia | D25: 500
B26: Paciente | C26: Dmax | D26: 5136
A46: Si es necesario agregar mas lineas de constraints, revisar el codigo. Hardcodeado hasta este valor de fila. RL

Sheet VMI+BOOST SEC
A2: Prescripción: | B2: VMI+BOOST SEC | D2: =IF($B$2=RIGHT(CELL("filename",$B$2),LEN(CELL("filename",$B$2))-FIND("]",CELL("filename",$B$2))), "Todo OK ", "No coincide nombre del template con nombre de Prescripción") -> Todo OK
A4: Estructura | B4: Dosis total (cGy) | C4: Dosis diaria (cGy) | D4: Nro de fx | E4: Nro de etapa | G4: Protocolo Imágenes
A5: PTV_VMI | B5: 4005 | C5: 267 | D5: 15 | E5: 1 | G5: Tg interno + Tg externo - Semanal + Setup Boost
A6: PTV_LUMP | B6: 4005 | C6: 267 | D6: 15 | E6: 1
A7: PTV_LUMP_E | B7: 1068 | C7: 267 | D7: 4 | E7: 2
A9: Tipo de Estructura | B9: Estructura | C9: Tipo de Constraint | D9: Ideal | E9: Valor ref aux (dvh) | F9: Aceptable | G9: Valor ref limite aceptable aux (dvh)
A10: target | B10: PTV_VMI | C10: V(D)>V_% | D10: 3885 | E10: 95 | F10: 3805 | G10: 95
C11: V(D)<V_% | D11: 4800 | E11: 35
C12: V(D)<V_% | D12: 4320 | E12: 50
C13: Dmax | D13: 4285
B14: PTV_LUMP | C14: V(D)>V_% | D14: 3885 | E14: 95 | F14: 3805 | G14: 95
C15: Dmax | D15: 4285
B16: PTV_LUMP_E | C16: V(D)>V_% | D16: 1036 | E16: 95 | F16: 1015 | G16: 95
A17: oar | B17: Mama_D | C17: Dmax | D17: 240 | F17: 384
C18: V(D)<V_% | D18: 144 | E18: 5 | F18: 240 | G18: 5
B19: Pulmon_I | C19: V(D)<V_% | D19: 1200 | E19: 15 | F19: 1200 | G19: 20
C20: V(D)<V_% | D20: 800 | E20: 30 | F20: 800 | G20: 35
C21: V(D)<V_% | D21: 400 | E21: 40 | F21: 400 | G21: 55
B22: Pulmon_D | C22: V(D)<V_% | D22: 400 | E22: 10
B23: Corazon | C23: V(D)<V_% | D23: 1600 | E23: 5
C24: V(D)<V_% | D24: 800 | E24: 30
C25: Dmedia | D25: 320 | F25: 400
B26: Paciente | C26: Dmax | D26: 5128
A46: Si es necesario agregar mas lineas de constraints, revisar el codigo. Hardcodeado hasta este valor de fila. RL

Sheet VMD+BOOST SEC
A2: Prescripción: | B2: VMD+BOOST SEC | D2: =IF($B$2=RIGHT(CELL("filename",$B$2),LEN(CELL("filename",$B$2))-FIND("]",CELL("filename",$B$2))), "Todo OK ", "No coincide nombre del template con nombre de Prescripción") -> Todo OK
A4: Estructura | B4: Dosis total (cGy) | C4: Dosis diaria (cGy) | D4: Nro de fx | E4: Nro de etapa | G4: Protocolo Imágenes
A5: PTV_VMD | B5: 4005 | C5: 267 | D5: 15 | E5: 1 | G5: Tg interno + Tg externo - Semanal + Setup Boost
A6: PTV_LUMP | B6: 4005 | C6: 267 | D6: 15 | E6: 1
A7: PTV_LUMP_E | B7: 1068 | C7: 267 | D7: 4 | E7: 2
A9: Tipo de Estructura | B9: Estructura | C9: Tipo de Constraint | D9: Ideal | E9: Valor ref aux (dvh) | F9: Aceptable | G9: Valor ref limite aceptable aux (dvh)
A10: target | B10: PTV_VMD | C10: V(D)>V_% | D10: 3885 | E10: 95 | F10: 3805 | G10: 95
C11: V(D)<V_% | D11: 4800 | E11: 35
C12: V(D)<V_% | D12: 4320 | E12: 50
C13: Dmax | D13: 4285
B14: PTV_LUMP | C14: V(D)>V_% | D14: 3885 | E14: 95 | F14: 3805 | G14: 95
C15: Dmax | D15: 4285
B16: PTV_LUMP_E | C16: V(D)>V_% | D16: 1036 | E16: 95 | F16: 1015 | G16: 95
A17: oar | B17: Mama_I | C17: Dmax | D17: 240 | F17: 384
C18: V(D)<V_% | D18: 144 | E18: 5 | F18: 240 | G18: 5
B19: Pulmon_D | C19: V(D)<V_% | D19: 1200 | E19: 15 | F19: 1200 | G19: 20
C20: V(D)<V_% | D20: 800 | E20: 30 | F20: 800 | G20: 35
C21: V(D)<V_% | D21: 400 | E21: 40 | F21: 400 | G21: 55
B22: Pulmon_I | C22: V(D)<V_% | D22: 400 | E22: 10
B23: Corazon | C23: V(D)<V_% | D23: 1600 | E23: 5
C24: V(D)<V_% | D24: 800 | E24: 30
C25: Dmedia | D25: 320 | F25: 400
B26: Higado | C26: V(D)<V_% | D26: 1500 | E26: 3
C27: Dmedia | D27: 500
B28: Paciente | C28: Dmax | D28: 5128
C29: Dmedia | D29: 500
A46: Si es necesario agregar mas lineas de constraints, revisar el codigo. Hardcodeado hasta este valor de fila. RL

Sheet VMI+LN
A2: Prescripción: | B2: VMI+LN | D2: =IF($B$2=RIGHT(CELL("filename",$B$2),LEN(CELL("filename",$B$2))-FIND("]",CELL("filename",$B$2))), "Todo OK ", "No coincide nombre del template con nombre de Prescripción") -> Todo OK
A4: Estructura | B4: Dosis total (cGy) | C4: Dosis diaria (cGy) | D4: Nro de fx | E4: Nro de etapa | G4: Protocolo Imágenes
A5: PTV_VMI | B5: 4005 | C5: 267 | D5: 15 | E5: 1 | G5: CBCT primer día + CBCT semanal o 2 veces por semana sujeto a setup
A6: PTV_LN | B6: 4005 | C6: 267 | D6: 15 | E6: 1
A9: Tipo de Estructura | B9: Estructura | C9: Tipo de Constraint | D9: Ideal | E9: Valor ref aux (dvh) | F9: Aceptable | G9: Valor ref limite aceptable aux (dvh)
A10: target | B10: PTV_VMI | C10: V(D)>V_% | D10: 3885 | E10: 95 | F10: 3805 | G10: 95
C11: Dmax | D11: 4285
B12: PTV_LN | C12: V(D)>V_% | D12: 3885 | E12: 95 | F12: 3805 | G12: 95
C13: Dmax | D13: 4285
A14: oar | B14: Mama_D | C14: V(D)<V_% | D14: 300 | E14: 10 | F14: 500 | G14: 10
B15: Pulmon_I | C15: V(D)<V_% | D15: 1800 | E15: 35 | F15: 1800 | G15: 40
B16: Pulmon_D | C16: V(D)<V_% | D16: 480 | E16: 10 | F16: 480 | G16: 15
B17: Corazon | C17: V(D)<V_% | D17: 2250 | E17: 2
C18: Dmedia | D18: 300 | F18: 500
B19: Medula | C19: Dmax | D19: 2003
B20: Humero_I | C20: Dmax | D20: 4000
B21: Tiroides | C21: V(D)<V_% | D21: 3750 | E21: 50
B22: Esofago | C22: V(D)<V_% | D22: 4005 | E22: 2 | F22: 4005 | G22: 5
C23: V(D)<V_% | D23: 3400 | E23: 50
B24: Paciente | C24: Dmax | D24: 4285
A46: Si es necesario agregar mas lineas de constraints, revisar el codigo. Hardcodeado hasta este valor de fila. RL

Sheet VMD+LN
A2: Prescripción: | B2: VMD+LN | D2: =IF($B$2=RIGHT(CELL("filename",$B$2),LEN(CELL("filename",$B$2))-FIND("]",CELL("filename",$B$2))), "Todo OK ", "No coincide nombre del template con nombre de Prescripción") -> Todo OK
A4: Estructura | B4: Dosis total (cGy) | C4: Dosis diaria (cGy) | D4: Nro de fx | E4: Nro de etapa | G4: Protocolo Imágenes
A5: PTV_VMD | B5: 4005 | C5: 267 | D5: 15 | E5: 1 | G5: CBCT primer día + CBCT semanal o 2 veces por semana sujeto a setup
A6: PTV_LN | B6: 4005 | C6: 267 | D6: 15 | E6: 1
A9: Tipo de Estructura | B9: Estructura | C9: Tipo de Constraint | D9: Ideal | E9: Valor ref aux (dvh) | F9: Aceptable | G9: Valor ref limite aceptable aux (dvh)
A10: target | B10: PTV_VMD | C10: V(D)>V_% | D10: 3885 | E10: 95 | F10: 3805 | G10: 95
C11: Dmax | D11: 4285
B12: PTV_LN | C12: V(D)>V_% | D12: 3885 | E12: 95 | F12: 3805
C13: Dmax | D13: 4285
A14: oar | B14: Mama_I | C14: V(D)<V_% | D14: 300 | E14: 10 | F14: 500 | G14: 10
B15: Pulmon_D | C15: V(D)<V_% | D15: 1800 | E15: 35 | F15: 1800 | G15: 40
B16: Pulmon_I | C16: V(D)<V_% | D16: 480 | E16: 10 | F16: 480 | G16: 15
B17: Corazon | C17: V(D)<V_% | D17: 2250 | E17: 2
C18: Dmedia | D18: 300 | F18: 500
B19: Medula | C19: Dmax | D19: 2003
B20: Humero_D | C20: Dmax | D20: 4000
B21: Tiroides | C21: V(D)<V_% | D21: 3750 | E21: 50
B22: Esofago | C22: V(D)<V_% | D22: 4005 | E22: 2 | F22: 4005 | G22: 5
C23: V(D)<V_% | D23: 3400 | E23: 50
B24: Higado | C24: V(D)<V_% | D24: 1500 | E24: 3
C25: Dmedia | D25: 500
B26: Paciente | C26: Dmedia | D26: 4285
A46: Si es necesario agregar mas lineas de constraints, revisar el codigo. Hardcodeado hasta este valor de fila. RL

Sheet VMI+LN+BOOST INT
A2: Prescripción: | B2: VMI+LN+BOOST INT | D2: =IF($B$2=RIGHT(CELL("filename",$B$2),LEN(CELL("filename",$B$2))-FIND("]",CELL("filename",$B$2))), "Todo OK ", "No coincide nombre del template con nombre de Prescripción") -> Todo OK
A4: Estructura | B4: Dosis total (cGy) | C4: Dosis diaria (cGy) | D4: Nro de fx | E4: Nro de etapa | G4: Protocolo Imágenes
A5: PTV_VMI | B5: 4005 | C5: 267 | D5: 15 | E5: 1 | G5: CBCT primer día + CBCT semanal o 2 veces por semana sujeto a setup
A6: PTV_LN | B6: 4005 | C6: 267 | D6: 15 | E6: 1
A7: PTV_LUMP | B7: 4800 | C7: 320 | D7: 15 | E7: 1
A10: Tipo de Estructura | B10: Estructura | C10: Tipo de Constraint | D10: Ideal | E10: Valor ref aux (dvh) | F10: Aceptable | G10: Valor ref limite aceptable aux (dvh)
A11: target | B11: PTV_VMI | C11: V(D)>V_% | D11: 3885 | E11: 95 | F11: 3805 | G11: 95
C12: V(D)<V_% | D12: 4320 | E12: 50
C13: V(D)<V_% | D13: 4800 | E13: 35
B14: PTV_LN | C14: V(D)>V_% | D14: 3885 | E14: 95 | F14: 3805 | G14: 95
C15: Dmax | D15: 4285
B16: PTV_LUMP | C16: V(D)>V_% | D16: 4656 | E16: 95
C17: V(D)<V_% | D17: 5280 | E17: 5
C18: Dmax | D18: 5376
A19: oar | B19: Mama_D | C19: V(D)<V_% | D19: 300 | E19: 10 | F19: 500 | G19: 10
B20: Pulmon_I | C20: V(D)<V_% | D20: 1800 | E20: 35 | F20: 1800 | G20: 40
B21: Pulmon_D | C21: V(D)<V_% | D21: 480 | E21: 10 | F21: 480 | G21: 15
B22: Corazon | C22: V(D)<V_% | D22: 2250 | E22: 2
C23: Dmedia | D23: 300 | F23: 500
B24: Medula | C24: Dmax | D24: 2003
B25: Humero_I | C25: Dmax | D25: 4000
B26: Tiroides | C26: V(D)<V_% | D26: 3750 | E26: 50
B27: Esofago | C27: V(D)<V_% | D27: 4005 | E27: 2 | F27: 4005 | G27: 5
C28: V(D)<V_% | D28: 3400 | E28: 50
B29: Paciente | C29: Dmax | D29: 5376
A46: Si es necesario agregar mas lineas de constraints, revisar el codigo. Hardcodeado hasta este valor de fila. RL

Sheet VMD+LN+BOOST INT
A2: Prescripción: | B2: VMD+LN+BOOST INT | D2: =IF($B$2=RIGHT(CELL("filename",$B$2),LEN(CELL("filename",$B$2))-FIND("]",CELL("filename",$B$2))), "Todo OK ", "No coincide nombre del template con nombre de Prescripción") -> Todo OK
A4: Estructura | B4: Dosis total (cGy) | C4: Dosis diaria (cGy) | D4: Nro de fx | E4: Nro de etapa | G4: Protocolo Imágenes
A5: PTV_VMD | B5: 4005 | C5: 267 | D5: 15 | E5: 1 | G5: CBCT primer día + CBCT semanal o 2 veces por semana sujeto a setup
A6: PTV_LN | B6: 4005 | C6: 267 | D6: 15 | E6: 1
A7: PTV_LUMP | B7: 4800 | C7: 320 | D7: 15 | E7: 1
A10: Tipo de Estructura | B10: Estructura | C10: Tipo de Constraint | D10: Ideal | E10: Valor ref aux (dvh) | F10: Aceptable | G10: Valor ref limite aceptable aux (dvh)
A11: target | B11: PTV_VMD | C11: V(D)>V_% | D11: 3885 | E11: 95 | F11: 3805 | G11: 95
C12: V(D)<V_% | D12: 4320 | E12: 50
C13: V(D)<V_% | D13: 4800 | E13: 35
B14: PTV_LN | C14: V(D)>V_% | D14: 3885 | E14: 95 | F14: 3805 | G14: 95
C15: Dmax | D15: 4285
B16: PTV_LUMP | C16: V(D)>V_% | D16: 4656 | E16: 95
C17: V(D)<V_% | D17: 5280 | E17: 5
C18: Dmax | D18: 5376
A19: oar | B19: Mama_I | C19: V(D)<V_% | D19: 300 | E19: 10 | F19: 500 | G19: 10
B20: Pulmon_D | C20: V(D)<V_% | D20: 1800 | E20: 35 | F20: 1800 | G20: 40
B21: Pulmon_I | C21: V(D)<V_% | D21: 480 | E21: 10 | F21: 480 | G21: 15
B22: Corazon | C22: V(D)<V_% | D22: 2250 | E22: 2
C23: Dmedia | D23: 300 | F23: 500
B24: Medula | C24: Dmax | D24: 2003
B25: Humero_D | C25: Dmax | D25: 4000
B26: Tiroides | C26: V(D)<V_% | D26: 3750 | E26: 50
B27: Esofago | C27: V(D)<V_% | D27: 4005 | E27: 2 | F27: 4005 | G27: 5
C28: V(D)<V_% | D28: 3400 | E28: 50
B29: Higado | C29: V(D)<V_% | D29: 1500 | E29: 3
C30: Dmedia | D30: 500
B31: Paciente | C31: Dmax | D31: 5376
A46: Si es necesario agregar mas lineas de constraints, revisar el codigo. Hardcodeado hasta este valor de fila. RL

Sheet VM_BILAT+BOOST INT
A2: Prescripción: | B2: VM_BILAT+BOOST INT | D2: =IF($B$2=RIGHT(CELL("filename",$B$2),LEN(CELL("filename",$B$2))-FIND("]",CELL("filename",$B$2))), "Todo OK ", "No coincide nombre del template con nombre de Prescripción") -> Todo OK
A4: Estructura | B4: Dosis total (cGy) | C4: Dosis diaria (cGy) | D4: Nro de fx | E4: Nro de etapa | G4: Protocolo Imágenes
A5: PTV_VMI | B5: 4005 | C5: 267 | D5: 15 | E5: 1 | G5: Definir previo a setup
A6: PTV_VMD | B6: 4005 | C6: 267 | D6: 15 | E6: 1
A7: PTV_LUMP_I | B7: 4800 | C7: 320 | D7: 15 | E7: 1
A8: PTV_LUMP_D | B8: 4800 | C8: 320 | D8: 15 | E8: 1
A10: Tipo de Estructura | B10: Estructura | C10: Tipo de Constraint | D10: Ideal | E10: Valor ref aux (dvh) | F10: Aceptable | G10: Valor ref limite aceptable aux (dvh)
A11: target | B11: PTV_VMI | C11: V(D)>V_% | D11: 3885 | E11: 95 | F11: 3805 | G11: 95
C12: V(D)<V_% | D12: 4320 | E12: 50
C13: V(D)<V_% | D13: 4800 | E13: 35
B14: PTV_VMD | C14: V(D)>V_% | D14: 3885 | E14: 95 | F14: 3805 | G14: 95
C15: V(D)<V_% | D15: 4320 | E15: 50
C16: V(D)<V_% | D16: 4800 | E16: 35
B17: PTV_LUMP_I | C17: V(D)>V_% | D17: 4656 | E17: 95
C18: V(D)<V_% | D18: 5280 | E18: 5
C19: Dmax | D19: 5376
B20: PTV_LUMP_D | C20: V(D)>V_% | D20: 4656 | E20: 95
C21: V(D)<V_% | D21: 5280 | E21: 5
C22: Dmax | D22: 5376
A23: oar | B23: Pulmon_I | C23: V(D)<V_% | D23: 1200 | E23: 15 | F23: 1200 | G23: 20
C24: V(D)<V_% | D24: 800 | E24: 30 | F24: 800 | G24: 35
C25: V(D)<V_% | D25: 400 | E25: 40 | F25: 400 | G25: 55
B26: Pulmon_D | C26: V(D)<V_% | D26: 1200 | E26: 15 | F26: 1200 | G26: 20
C27: V(D)<V_% | D27: 800 | E27: 30 | F27: 800 | G27: 35
C28: V(D)<V_% | D28: 400 | E28: 40 | F28: 400 | G28: 55
B29: Corazon | C29: V(D)<V_% | D29: 1600 | E29: 5
C30: V(D)<V_% | D30: 800 | E30: 30
C31: Dmedia | D31: 320 | F31: 400
B32: Higado | C32: V(D)<V_% | D32: 1500 | E32: 3
C33: Dmedia | D33: 500
B34: Paciente | C34: Dmax | D34: 5136
A46: Si es necesario agregar mas lineas de constraints, revisar el codigo. Hardcodeado hasta este valor de fila. RL

Sheet VM_BILAT+LN_I+BOOST INT
A2: Prescripción: | B2: VM_BILAT+LN_I+BOOST INT | D2: =IF($B$2=RIGHT(CELL("filename",$B$2),LEN(CELL("filename",$B$2))-FIND("]",CELL("filename",$B$2))), "Todo OK ", "No coincide nombre del template con nombre de Prescripción") -> Todo OK
A4: Estructura | B4: Dosis total (cGy) | C4: Dosis diaria (cGy) | D4: Nro de fx | E4: Nro de etapa | G4: Protocolo Imágenes
A5: PTV_VMI | B5: 4005 | C5: 267 | D5: 15 | E5: 1 | G5: Definir previo a setup
A6: PTV_VMD | B6: 4005 | C6: 267 | D6: 15 | E6: 1
A7: PTV_LN_I | B7: 4005 | C7: 267 | D7: 15 | E7: 1
A8: PTV_LUMP_I | B8: 4800 | C8: 320 | D8: 15 | E8: 1
A9: PTV_LUMP_D | B9: 4800 | C9: 320 | D9: 15 | E9: 1
A11: Tipo de Estructura | B11: Estructura | C11: Tipo de Constraint | D11: Ideal | E11: Valor ref aux (dvh) | F11: Aceptable | G11: Valor ref limite aceptable aux (dvh)
A12: target | B12: PTV_VMI | C12: V(D)>V_% | D12: 3885 | E12: 95 | F12: 3805 | G12: 95
C13: V(D)<V_% | D13: 4320 | E13: 50
C14: V(D)<V_% | D14: 4800 | E14: 35
B15: PTV_VMD | C15: V(D)>V_% | D15: 3885 | E15: 95 | F15: 3805 | G15: 95
C16: V(D)<V_% | D16: 4320 | E16: 50
C17: V(D)<V_% | D17: 4800 | E17: 35
B18: PTV_LN_I | C18: V(D)>V_% | D18: 3885 | E18: 95 | F18: 3805 | G18: 95
C19: Dmax | D19: 4285
B20: PTV_LUMP_I | C20: V(D)>V_% | D20: 4656 | E20: 95
C21: V(D)<V_% | D21: 5280 | E21: 5
C22: Dmax | D22: 5376
B23: PTV_LUMP_D | C23: V(D)>V_% | D23: 4656 | E23: 95
C24: V(D)<V_% | D24: 5280 | E24: 5
C25: Dmax | D25: 5376
A26: oar | B26: Pulmon_I | C26: V(D)<V_% | D26: 1800 | E26: 35 | F26: 1800 | G26: 40
B27: Pulmon_D | C27: V(D)<V_% | D27: 1200 | E27: 15 | F27: 1200 | G27: 20
C28: V(D)<V_% | D28: 800 | E28: 30 | F28: 800 | G28: 35
C29: V(D)<V_% | D29: 400 | E29: 40 | F29: 400 | G29: 55
B30: Corazon | C30: V(D)<V_% | D30: 2250 | E30: 2
C31: Dmedia | D31: 300 | F31: 500
B32: Medula | C32: Dmax | D32: 2003
B33: Humero_I | C33: Dmax | D33: 4000
B34: Humero_D | C34: Dmax | D34: 4000
B35: Tiroides | C35: V(D)<V_% | D35: 3750 | E35: 50
B36: Esofago | C36: V(D)<V_% | D36: 4005 | E36: 2 | F36: 4005 | G36: 5
C37: V(D)<V_% | D37: 3400 | E37: 50
B38: Paciente | C38: Dmax | D38: 5376
A47: Si es necesario agregar mas lineas de constraints, revisar el codigo. Hardcodeado hasta este valor de fila. RL

Sheet VM_BILAT+LN_D+BOOST INT
A2: Prescripción: | B2: VM_BILAT+LN_D+BOOST INT | D2: =IF($B$2=RIGHT(CELL("filename",$B$2),LEN(CELL("filename",$B$2))-FIND("]",CELL("filename",$B$2))), "Todo OK ", "No coincide nombre del template con nombre de Prescripción") -> Todo OK
A4: Estructura | B4: Dosis total (cGy) | C4: Dosis diaria (cGy) | D4: Nro de fx | E4: Nro de etapa | G4: Protocolo Imágenes
A5: PTV_VMI | B5: 4005 | C5: 267 | D5: 15 | E5: 1 | G5: Definir previo a setup
A6: PTV_VMD | B6: 4005 | C6: 267 | D6: 15 | E6: 1
A7: PTV_LN_D | B7: 4005 | C7: 267 | D7: 15 | E7: 1
A8: PTV_LUMP_I | B8: 4800 | C8: 320 | D8: 15 | E8: 1
A9: PTV_LUMP_D | B9: 4800 | C9: 320 | D9: 15 | E9: 1
A11: Tipo de Estructura | B11: Estructura | C11: Tipo de Constraint | D11: Ideal | E11: Valor ref aux (dvh) | F11: Aceptable | G11: Valor ref limite aceptable aux (dvh)
A12: target | B12: PTV_VMI | C12: V(D)>V_% | D12: 3885 | E12: 95 | F12: 3805 | G12: 95
C13: V(D)<V_% | D13: 4320 | E13: 50
C14: V(D)<V_% | D14: 4800 | E14: 35
B15: PTV_VMD | C15: V(D)>V_% | D15: 3885 | E15: 95 | F15: 3805 | G15: 95
C16: V(D)<V_% | D16: 4320 | E16: 50
C17: V(D)<V_% | D17: 4800 | E17: 35
B18: PTV_LN_D | C18: V(D)>V_% | D18: 3885 | E18: 95 | F18: 3805 | G18: 95
C19: Dmax | D19: 4285
B20: PTV_LUMP_I | C20: V(D)>V_% | D20: 4656 | E20: 95
C21: V(D)<V_% | D21: 5280 | E21: 5
C22: Dmax | D22: 5376
B23: PTV_LUMP_D | C23: V(D)>V_% | D23: 4656 | E23: 95
C24: V(D)<V_% | D24: 5280 | E24: 5
C25: Dmax | D25: 5376
A26: oar | B26: Pulmon_D | C26: V(D)<V_% | D26: 1800 | E26: 35 | F26: 1800 | G26: 40
B27: Pulmon_I | C27: V(D)<V_% | D27: 1200 | E27: 15 | F27: 1200 | G27: 20
C28: V(D)<V_% | D28: 800 | E28: 30 | F28: 800 | G28: 35
C29: V(D)<V_% | D29: 400 | E29: 40 | F29: 400 | G29: 55
B30: Corazon | C30: V(D)<V_% | D30: 2250 | E30: 2
C31: Dmedia | D31: 300 | F31: 500
B32: Medula | C32: Dmax | D32: 2003
B33: Humero_D | C33: Dmax | D33: 4000
B34: Humero_I | C34: Dmax | D34: 4000
B35: Tiroides | C35: V(D)<V_% | D35: 3750 | E35: 50
B36: Esofago | C36: V(D)<V_% | D36: 4005 | E36: 2 | F36: 4005 | G36: 5
C37: V(D)<V_% | D37: 3400 | E37: 50
B38: Paciente | C38: Dmax | D38: 5376
A47: Si es necesario agregar mas lineas de constraints, revisar el codigo. Hardcodeado hasta este valor de fila. RL

Sheet VMI+LN+CMI+BOOST INT
A2: Prescripción: | B2: VMI+LN+CMI+BOOST INT | D2: =IF($B$2=RIGHT(CELL("filename",$B$2),LEN(CELL("filename",$B$2))-FIND("]",CELL("filename",$B$2))), "Todo OK ", "No coincide nombre del template con nombre de Prescripción") -> Todo OK
A4: Estructura | B4: Dosis total (cGy) | C4: Dosis diaria (cGy) | D4: Nro de fx | E4: Nro de etapa | G4: Protocolo Imágenes
A5: PTV_VMI | B5: 4005 | C5: 267 | D5: 15 | E5: 1 | G5: CBCT primer día + CBCT semanal o 2 veces por semana sujeto a setup
A6: PTV_LN | B6: 4005 | C6: 267 | D6: 15 | E6: 1
A7: PTV_LUMP | B7: 4800 | C7: 320 | D7: 15 | E7: 1
A8: PTV_CMI | B8: 4005 | C8: 267 | D8: 15 | E8: 1
A11: Tipo de Estructura | B11: Estructura | C11: Tipo de Constraint | D11: Ideal | E11: Valor ref aux (dvh) | F11: Aceptable | G11: Valor ref limite aceptable aux (dvh)
A12: target | B12: PTV_VMI | C12: V(D)>V_% | D12: 3885 | E12: 95 | F12: 3805 | G12: 95
C13: V(D)<V_% | D13: 4320 | E13: 50
C14: V(D)<V_% | D14: 4800 | E14: 35
B15: PTV_LN | C15: V(D)>V_% | D15: 3805 | E15: 95
C16: Dmax | D16: 4285
B17: PTV_CMI | C17: V(D)>V_% | D17: 3805 | E17: 95
C18: Dmax | D18: 4285
B19: PTV_LUMP | C19: V(D)>V_% | D19: 4656 | E19: 95
C20: V(D)<V_% | D20: 5280 | E20: 5
A21: oar | C21: Dmax | D21: 5376
B22: Mama_D | C22: V(D)<V_% | D22: 300 | E22: 10 | F22: 500 | G22: 10
B23: Pulmon_I | C23: V(D)<V_% | D23: 1800 | E23: 35 | F23: 1800 | G23: 40
B24: Pulmon_D | C24: V(D)<V_% | D24: 480 | E24: 10 | F24: 480 | G24: 15
B25: Corazon | C25: V(D)<V_% | D25: 2250 | E25: 2
C26: Dmedia | D26: 300 | F26: 500
B27: Medula | C27: Dmax | D27: 2003
B28: Humero_I | C28: Dmax | D28: 4000
B29: Tiroides | C29: V(D)<V_% | D29: 3750 | E29: 50
B30: Esofago | C30: V(D)<V_% | D30: 4005 | E30: 2 | F30: 4005 | G30: 5
C31: V(D)<V_% | D31: 3400 | E31: 50
B32: Paciente | C32: Dmax | D32: 5136
A46: Si es necesario agregar mas lineas de constraints, revisar el codigo. Hardcodeado hasta este valor de fila. RL

Sheet VMD+LN+CMI+BOOST INT
A2: Prescripción: | B2: VMD+LN+CMI+BOOST INT | D2: =IF($B$2=RIGHT(CELL("filename",$B$2),LEN(CELL("filename",$B$2))-FIND("]",CELL("filename",$B$2))), "Todo OK ", "No coincide nombre del template con nombre de Prescripción") -> Todo OK
A4: Estructura | B4: Dosis total (cGy) | C4: Dosis diaria (cGy) | D4: Nro de fx | E4: Nro de etapa | G4: Protocolo Imágenes
A5: PTV_VMD | B5: 4005 | C5: 267 | D5: 15 | E5: 1 | G5: CBCT primer día + CBCT semanal o 2 veces por semana sujeto a setup
A6: PTV_LN | B6: 4005 | C6: 267 | D6: 15 | E6: 1
A7: PTV_LUMP | B7: 4800 | C7: 320 | D7: 15 | E7: 1
A8: PTV_CMI | B8: 4005 | C8: 267 | D8: 15 | E8: 1
A11: Tipo de Estructura | B11: Estructura | C11: Tipo de Constraint | D11: Ideal | E11: Valor ref aux (dvh) | F11: Aceptable | G11: Valor ref limite aceptable aux (dvh)
A12: target | B12: PTV_VMD | C12: V(D)>V_% | D12: 3885 | E12: 95 | F12: 3805 | G12: 95
C13: V(D)<V_% | D13: 4320 | E13: 50
C14: V(D)<V_% | D14: 4800 | E14: 35
B15: PTV_LN | C15: V(D)>V_% | D15: 3805 | E15: 95
C16: Dmax | D16: 4285
B17: PTV_CMI | C17: V(D)>V_% | D17: 3805 | E17: 95
C18: Dmax | D18: 4285
B19: PTV_LUMP | C19: V(D)>V_% | D19: 4656 | E19: 95
C20: V(D)<V_% | D20: 5280 | E20: 5
A21: oar | C21: Dmax | D21: 5376
B22: Mama_I | C22: V(D)<V_% | D22: 300 | E22: 10 | F22: 500 | G22: 10
B23: Pulmon_D | C23: V(D)<V_% | D23: 1800 | E23: 35 | F23: 1800 | G23: 40
B24: Pulmon_I | C24: V(D)<V_% | D24: 480 | E24: 10 | F24: 480 | G24: 15
B25: Corazon | C25: V(D)<V_% | D25: 2250 | E25: 2
C26: Dmedia | D26: 300 | F26: 500
B27: Medula | C27: Dmax | D27: 2003
B28: Humero_D | C28: Dmax | D28: 4000
B29: Tiroides | C29: V(D)<V_% | D29: 3750 | E29: 50
B30: Esofago | C30: V(D)<V_% | D30: 4005 | E30: 2 | F30: 4005 | G30: 5
C31: V(D)<V_% | D31: 3400 | E31: 50
B32: Higado | C32: V(D)<V_% | D32: 1500 | E32: 3
C33: Dmedia | D33: 500
B34: Paciente | C34: Dmax | D34: 5136
A46: Si es necesario agregar mas lineas de constraints, revisar el codigo. Hardcodeado hasta este valor de fila. RL

Sheet LECHO_I
A2: Prescripción: | B2: LECHO_I | D2: =IF($B$2=RIGHT(CELL("filename",$B$2),LEN(CELL("filename",$B$2))-FIND("]",CELL("filename",$B$2))), "Todo OK ", "No coincide nombre del template con nombre de Prescripción") -> Todo OK
A4: Estructura | B4: Dosis total (cGy) | C4: Dosis diaria (cGy) | D4: Nro de fx | E4: Nro de etapa | G4: Protocolo Imágenes
A5: PTV_LECHO_I | B5: 4005 | C5: 267 | D5: =LECHO_I!$B5/LECHO_I!$C5 -> 15 | E5: 1 | G5: Tg interno + Tg externo - Semanal
A7: Tipo de Estructura | B7: Estructura | C7: Tipo de Constraint | D7: Ideal | E7: Valor ref aux (dvh) | F7: Aceptable | G7: Valor ref limite aceptable aux (dvh)
A8: target | B8: PTV_LECHO_I | C8: V(D)>V_% | D8: 3885 | E8: 95 | F8: 3805 | G8: 95
C9: Dmax | D9: 4285
A10: oar | B10: Mama_D | C10: Dmax | D10: 240 | F10: 384
C11: V(D)<V_% | D11: 144 | E11: 5 | F11: 240 | G11: 5
B12: Pulmon_I | C12: V(D)<V_% | D12: 1200 | E12: 15 | F12: 1200 | G12: 20
C13: V(D)<V_% | D13: 800 | E13: 30 | F13: 800 | G13: 35
C14: V(D)<V_% | D14: 400 | E14: 40 | F14: 400 | G14: 55
B15: Pulmon_D | C15: V(D)<V_% | D15: 400 | E15: 10
B16: Corazon | C16: V(D)<V_% | D16: 1600 | E16: 5
C17: V(D)<V_% | D17: 800 | E17: 30
C18: Dmedia | D18: 320 | F18: 400
B19: Paciente | C19: Dmax | D19: 4285
A46: Si es necesario agregar mas lineas de constraints, revisar el codigo. Hardcodeado hasta este valor de fila. RL

Sheet LECHO_D
A2: Prescripción: | B2: LECHO_D | D2: =IF($B$2=RIGHT(CELL("filename",$B$2),LEN(CELL("filename",$B$2))-FIND("]",CELL("filename",$B$2))), "Todo OK ", "No coincide nombre del template con nombre de Prescripción") -> Todo OK
A4: Estructura | B4: Dosis total (cGy) | C4: Dosis diaria (cGy) | D4: Nro de fx | E4: Nro de etapa | G4: Protocolo Imágenes
A5: PTV_LECHO_D | B5: 4005 | C5: 267 | D5: =LECHO_D!$B5/LECHO_D!$C5 -> 15 | E5: 1 | G5: Tg interno + Tg externo - Semanal
A7: Tipo de Estructura | B7: Estructura | C7: Tipo de Constraint | D7: Ideal | E7: Valor ref aux (dvh) | F7: Aceptable | G7: Valor ref limite aceptable aux (dvh)
A8: target | B8: PTV_LECHO_D | C8: V(D)>V_% | D8: 3885 | E8: 95 | F8: 3805 | G8: 95
C9: Dmax | D9: 4285
A10: oar | B10: Mama_I | C10: Dmax | D10: 240 | F10: 384
C11: V(D)<V_% | D11: 144 | E11: 5 | F11: 240 | G11: 5
B12: Pulmon_D | C12: V(D)<V_% | D12: 1200 | E12: 15 | F12: 1200 | G12: 20
C13: V(D)<V_% | D13: 800 | E13: 30 | F13: 800 | G13: 35
C14: V(D)<V_% | D14: 400 | E14: 40 | F14: 400 | G14: 55
B15: Pulmon_I | C15: V(D)<V_% | D15: 400 | E15: 10
B16: Corazon | C16: V(D)<V_% | D16: 1600 | E16: 5
C17: V(D)<V_% | D17: 800 | E17: 30
C18: Dmedia | D18: 320 | F18: 400
B19: Higado | C19: V(D)<V_% | D19: 1500 | E19: 3
C20: Dmedia | D20: 500
B21: Paciente | C21: Dmax | D21: 4285
A46: Si es necesario agregar mas lineas de constraints, revisar el codigo. Hardcodeado hasta este valor de fila. RL

Sheet LECHO_I+LN
A2: Prescripción: | B2: LECHO_I+LN | D2: =IF($B$2=RIGHT(CELL("filename",$B$2),LEN(CELL("filename",$B$2))-FIND("]",CELL("filename",$B$2))), "Todo OK ", "No coincide nombre del template con nombre de Prescripción") -> Todo OK
A4: Estructura | B4: Dosis total (cGy) | C4: Dosis diaria (cGy) | D4: Nro de fx | E4: Nro de etapa | G4: Protocolo Imágenes
A5: PTV_LECHO_I | B5: 4005 | C5: 267 | D5: =B5/C5 -> 15 | E5: 1 | G5: CBCT primer día + CBCT semanal o 2 veces por semana sujeto a setup
A6: PTV_LN | B6: 4005 | C6: 267 | D6: =B6/C6 -> 15 | E6: 1
A9: Tipo de Estructura | B9: Estructura | C9: Tipo de Constraint | D9: Ideal | E9: Valor ref aux (dvh) | F9: Aceptable | G9: Valor ref limite aceptable aux (dvh)
A10: target | B10: PTV_LECHO_I | C10: V(D)>V_% | D10: 3885 | E10: 95 | F10: 3805 | G10: 95
C11: Dmax | D11: 4285
B12: PTV_LN | C12: V(D)>V_% | D12: 3805 | E12: 95
C13: Dmax | D13: 4285
A14: oar | B14: Mama_D | C14: V(D)<V_% | D14: 300 | E14: 10 | F14: 500 | G14: 10
B15: Pulmon_I | C15: V(D)<V_% | D15: 1800 | E15: 35 | F15: 1800 | G15: 40
B16: Pulmon_D | C16: V(D)<V_% | D16: 480 | E16: 10 | F16: 480 | G16: 15
B17: Corazon | C17: V(D)<V_% | D17: 2250 | E17: 2
C18: Dmedia | D18: 300 | F18: 500
B19: Medula | C19: Dmax | D19: 2003
B20: Humero_I | C20: Dmax | D20: 4000
B21: Tiroides | C21: V(D)<V_% | D21: 3750 | E21: 50
B22: Esofago | C22: V(D)<V_% | D22: 4005 | E22: 2 | F22: 4005 | G22: 5
C23: V(D)<V_% | D23: 3400 | E23: 50
B24: Paciente | C24: Dmax | D24: 4285
A46: Si es necesario agregar mas lineas de constraints, revisar el codigo. Hardcodeado hasta este valor de fila. RL

Sheet LECHO_D+LN
A2: Prescripción: | B2: LECHO_D+LN | D2: =IF($B$2=RIGHT(CELL("filename",$B$2),LEN(CELL("filename",$B$2))-FIND("]",CELL("filename",$B$2))), "Todo OK ", "No coincide nombre del template con nombre de Prescripción") -> Todo OK
A4: Estructura | B4: Dosis total (cGy) | C4: Dosis diaria (cGy) | D4: Nro de fx | E4: Nro de etapa | G4: Protocolo Imágenes
A5: PTV_LECHO_D | B5: 4005 | C5: 267 | D5: =B5/C5 -> 15 | E5: 1 | G5: CBCT primer día + CBCT semanal o 2 veces por semana sujeto a setup
A6: PTV_LN | B6: 4005 | C6: 267 | D6: =B6/C6 -> 15 | E6: 1
A9: Tipo de Estructura | B9: Estructura | C9: Tipo de Constraint | D9: Ideal | E9: Valor ref aux (dvh) | F9: Aceptable | G9: Valor ref limite aceptable aux (dvh)
A10: target | B10: PTV_LECHO_D | C10: V(D)>V_% | D10: 3885 | E10: 95 | F10: 3805 | G10: 95
C11: Dmax | D11: 4285
B12: PTV_LN | C12: V(D)>V_% | D12: 3805 | E12: 95
C13: Dmax | D13: 4285
A14: oar | B14: Mama_I | C14: V(D)<V_% | D14: 300 | E14: 10 | F14: 500 | G14: 10
B15: Pulmon_D | C15: V(D)<V_% | D15: 1800 | E15: 35 | F15: 1800 | G15: 40
B16: Pulmon_I | C16: V(D)<V_% | D16: 480 | E16: 10 | F16: 480 | G16: 15
B17: Corazon | C17: V(D)<V_% | D17: 2250 | E17: 2
C18: Dmedia | D18: 300 | F18: 500
B19: Medula | C19: Dmax | D19: 2003
B20: Humero_D | C20: Dmax | D20: 4000
B21: Tiroides | C21: V(D)<V_% | D21: 3750 | E21: 50
B22: Esofago | C22: V(D)<V_% | D22: 4005 | E22: 2 | F22: 4005 | G22: 5
C23: V(D)<V_% | D23: 3400 | E23: 50
B24: Higado | C24: V(D)<V_% | D24: 1500 | E24: 3
C25: Dmedia | D25: 500
B26: Paciente | C26: Dmax | D26: 4285
A46: Si es necesario agregar mas lineas de constraints, revisar el codigo. Hardcodeado hasta este valor de fila. RL

Sheet LECHO_I+LN+CMI
A2: Prescripción: | B2: LECHO_I+LN+CMI | D2: =IF($B$2=RIGHT(CELL("filename",$B$2),LEN(CELL("filename",$B$2))-FIND("]",CELL("filename",$B$2))), "Todo OK ", "No coincide nombre del template con nombre de Prescripción") -> Todo OK
A4: Estructura | B4: Dosis total (cGy) | C4: Dosis diaria (cGy) | D4: Nro de fx | E4: Nro de etapa | G4: Protocolo Imágenes
A5: PTV_LECHO_I | B5: 4005 | C5: 267 | D5: 15 | E5: 1 | G5: CBCT primer día + CBCT semanal o 2 veces por semana sujeto a setup
A6: PTV_LN | B6: 4005 | C6: 267 | D6: 15 | E6: 1
A7: PTV_CMI | B7: 4005 | C7: 267 | D7: 15 | E7: 1
A10: Tipo de Estructura | B10: Estructura | C10: Tipo de Constraint | D10: Ideal | E10: Valor ref aux (dvh) | F10: Aceptable | G10: Valor ref limite aceptable aux (dvh)
A11: target | B11: PTV_LECHO_I | C11: V(D)>V_% | D11: 3885 | E11: 95 | F11: 3805 | G11: 95
C12: Dmax | D12: 4285
B13: PTV_LN | C13: V(D)>V_% | D13: 3805 | E13: 95
C14: Dmax | D14: 4285
B15: PTV_CMI | C15: V(D)>V_% | D15: 3805 | E15: 95
C16: Dmax | D16: 4285
A17: oar | B17: Mama_D | C17: V(D)<V_% | D17: 300 | E17: 10 | F17: 500 | G17: 10
B18: Pulmon_I | C18: V(D)<V_% | D18: 1800 | E18: 35 | F18: 1800 | G18: 40
B19: Pulmon_D | C19: V(D)<V_% | D19: 480 | E19: 10 | F19: 480 | G19: 15
B20: Corazon | C20: V(D)<V_% | D20: 2250 | E20: 2
C21: Dmedia | D21: 300 | F21: 500
B22: Medula | C22: Dmax | D22: 2003
B23: Humero_I | C23: Dmax | D23: 4000
B24: Esofago | C24: V(D)<V_% | D24: 4005 | E24: 2 | F24: 4005 | G24: 5
C25: V(D)<V_% | D25: 3400 | E25: 50
B26: Paciente | C26: Dmax | D26: 4285
A46: Si es necesario agregar mas lineas de constraints, revisar el codigo. Hardcodeado hasta este valor de fila. RL

Sheet LECHO_D+LN+CMI
A2: Prescripción: | B2: LECHO_D+LN+CMI | D2: =IF($B$2=RIGHT(CELL("filename",$B$2),LEN(CELL("filename",$B$2))-FIND("]",CELL("filename",$B$2))), "Todo OK ", "No coincide nombre del template con nombre de Prescripción") -> Todo OK
A4: Estructura | B4: Dosis total (cGy) | C4: Dosis diaria (cGy) | D4: Nro de fx | E4: Nro de etapa | G4: Protocolo Imágenes
A5: PTV_LECHO_D | B5: 4005 | C5: 267 | D5: 15 | E5: 1 | G5: CBCT primer día + CBCT semanal o 2 veces por semana sujeto a setup
A6: PTV_LN | B6: 4005 | C6: 267 | D6: 15 | E6: 1
A7: PTV_CMI | B7: 4005 | C7: 267 | D7: 15 | E7: 1
A10: Tipo de Estructura | B10: Estructura | C10: Tipo de Constraint | D10: Ideal | E10: Valor ref aux (dvh) | F10: Aceptable | G10: Valor ref limite aceptable aux (dvh)
A11: target | B11: PTV_LECHO_D | C11: V(D)>V_% | D11: 3885 | E11: 95 | F11: 3805 | G11: 95
C12: Dmax | D12: 4285
B13: PTV_LN | C13: V(D)>V_% | D13: 3805 | E13: 95
C14: Dmax | D14: 4285
B15: PTV_CMI | C15: V(D)>V_% | D15: 3805 | E15: 95
C16: Dmax | D16: 4285
A17: oar | B17: Mama_I | C17: V(D)<V_% | D17: 300 | E17: 10 | F17: 500 | G17: 10
B18: Pulmon_D | C18: V(D)<V_% | D18: 1800 | E18: 35 | F18: 1800 | G18: 40
B19: Pulmon_I | C19: V(D)<V_% | D19: 480 | E19: 10 | F19: 480 | G19: 15
B20: Corazon | C20: V(D)<V_% | D20: 2250 | E20: 2
C21: Dmedia | D21: 300 | F21: 500
B22: Medula | C22: Dmax | D22: 2003
B23: Humero_D | C23: Dmax | D23: 4000
B24: Tiroides | C24: V(D)<V_% | D24: 3750 | E24: 50
B25: Esofago | C25: V(D)<V_% | D25: 4005 | E25: 2 | F25: 4005 | G25: 5
C26: V(D)<V_% | D26: 3400 | E26: 50
B27: Higado | C27: V(D)<V_% | D27: 1500 | E27: 3
C28: Dmedia | D28: 500
B29: Paciente | C29: Dmax | D29: 4285
A46: Si es necesario agregar mas lineas de constraints, revisar el codigo. Hardcodeado hasta este valor de fila. RL

Sheet APBI MAMA_D
A2: Prescripción: | B2: APBI MAMA_D | D2: =IF($B$2=RIGHT(CELL("filename",$B$2),LEN(CELL("filename",$B$2))-FIND("]",CELL("filename",$B$2))), "Todo OK ", "No coincide nombre del template con nombre de Prescripción") -> Todo OK
A4: Estructura | B4: Dosis total (cGy) | C4: Dosis diaria (cGy) | D4: Nro de fx | E4: Nro de etapa | G4: Protocolo Imágenes
A5: PTV | B5: 3000 | C5: 600 | D5: ='APBI MAMA_D'!$B5/'APBI MAMA_D'!$C5 -> 5 | E5: 1 | G5: CBCT diario (SRS/SBRT)
A7: Tipo de Estructura | B7: Estructura | C7: Tipo de Constraint | D7: Ideal | E7: Valor ref aux (dvh) | F7: Aceptable | G7: Valor ref limite aceptable aux (dvh)
A8: target | B8: PTV | C8: V(D)>V_% | D8: 2940 | E8: 95 | F8: 2850 | G8: 95
C9: Dmax | D9: 3300
A10: oar | B10: Corazon | C10: V(D)<V_cc | D10: 500 | E10: 0.03 | F10: 1000 | G10: 0.1
C11: Dmedia | D11: 100
B12: Pulmon_D | C12: V(D)<V_% | D12: 1000 | E12: 5
C13: V(D)<V_cc | D13: 1500 | E13: 0.1
C14: Dmedia | D14: 300
B15: Pulmon_I | C15: Dmedia | D15: 100
B16: Mama_D-PTV | C16: V(D)<V_% | D16: 1500 | E16: 40
C17: V(D)<V_% | D17: 3000 | E17: 20 | F17: 3000 | G17: 25
C18: Dmedia | D18: 1200
B19: Mama_I | C19: Dmedia | D19: 100
C20: Dmax | D20: 300
B21: Piel | C21: V(D)<V_cc | D21: 3000 | E21: 0.2
C22: V(D)<V_cc | D22: 2700 | E22: 1
C23: V(D)<V_% | D23: 2400 | E23: 5
B24: Costillas | C24: V(D)<V_cc | D24: 3000 | E24: 0.1
C25: V(D)<V_cc | D25: 2700 | E25: 1
C26: Dmax | D26: 3200
B27: Paciente | C27: Dmax | D27: 3300
A46: Si es necesario agregar mas lineas de constraints, revisar el codigo. Hardcodeado hasta este valor de fila. RL

Sheet APBI MAMA_I
A2: Prescripción: | B2: APBI MAMA_I | D2: =IF($B$2=RIGHT(CELL("filename",$B$2),LEN(CELL("filename",$B$2))-FIND("]",CELL("filename",$B$2))), "Todo OK ", "No coincide nombre del template con nombre de Prescripción") -> Todo OK
A4: Estructura | B4: Dosis total (cGy) | C4: Dosis diaria (cGy) | D4: Nro de fx | E4: Nro de etapa | G4: Protocolo Imágenes
A5: PTV | B5: 3000 | C5: 600 | D5: ='APBI MAMA_I'!$B5/'APBI MAMA_I'!$C5 -> 5 | E5: 1 | G5: CBCT diario (SRS/SBRT)
A7: Tipo de Estructura | B7: Estructura | C7: Tipo de Constraint | D7: Ideal | E7: Valor ref aux (dvh) | F7: Aceptable | G7: Valor ref limite aceptable aux (dvh)
A8: target | B8: PTV | C8: V(D)>V_% | D8: 2940 | E8: 95 | F8: 2850 | G8: 95
C9: Dmax | D9: 3300
A10: oar | B10: Corazon | C10: V(D)<V_cc | D10: 500 | E10: 0.03 | F10: 1000 | G10: 0.1
C11: Dmedia | D11: 100
B12: Pulmon_I | C12: V(D)<V_% | D12: 1000 | E12: 5
C13: V(D)<V_cc | D13: 1500 | E13: 0.1
C14: Dmedia | D14: 300
B15: Pulmon_D | C15: Dmedia | D15: 100
B16: Mama_I-PTV | C16: V(D)<V_% | D16: 1500 | E16: 40
C17: V(D)<V_% | D17: 3000 | E17: 20 | F17: 3000 | G17: 25
C18: Dmedia | D18: 1200
B19: Mama_D | C19: Dmedia | D19: 100
C20: Dmax | D20: 300
B21: Piel | C21: V(D)<V_cc | D21: 3000 | E21: 0.2
C22: V(D)<V_cc | D22: 2700 | E22: 1
C23: V(D)<V_% | D23: 2400 | E23: 5
B24: Costillas | C24: V(D)<V_cc | D24: 3000 | E24: 0.1
C25: V(D)<V_cc | D25: 2700 | E25: 1
C26: Dmax | D26: 3200
B27: Paciente | C27: Dmax | D27: 3300
A46: Si es necesario agregar mas lineas de constraints, revisar el codigo. Hardcodeado hasta este valor de fila. RL

Sheet VEJIGA+LN 5500-20FX
A2: Prescripción: | B2: VEJIGA+LN 5500-20FX | D2: =IF($B$2=RIGHT(CELL("filename",$B$2),LEN(CELL("filename",$B$2))-FIND("]",CELL("filename",$B$2))), "Todo OK ", "No coincide nombre del template con nombre de Prescripción") -> Todo OK
A4: Estructura | B4: Dosis total (cGy) | C4: Dosis diaria (cGy) | D4: Nro de fx | E4: Nro de etapa | G4: Protocolo Imágenes
A5: PTV_T | B5: 5500 | C5: 275 | D5: ='VEJIGA+LN 5500-20FX'!$B5/'VEJIGA+LN 5500-20FX'!$C5 -> 20 | E5: 1 | G5: CBCT diario + CBCT primeros 3 días representativos para promedios
A6: PTV_LN | B6: 4500 | C6: 225 | D6: ='VEJIGA+LN 5500-20FX'!$B6/'VEJIGA+LN 5500-20FX'!$C6 -> 20 | E6: 1
A8: Tipo de Estructura | B8: Estructura | C8: Tipo de Constraint | D8: Ideal | E8: Valor ref aux (dvh) | F8: Aceptable | G8: Valor ref limite aceptable aux (dvh)
A9: target | B9: PTV_T | C9: V(D)>V_% | D9: 5390 | E9: 95
C10: Dmax | D10: 5885
B11: PTV_LN | C11: V(D)>V_% | D11: 4410 | E11: 95
A12: oar | B12: Recto | C12: V(D)<V_% | D12: 5500 | E12: 1 | F12: 5500 | G12: 5
C13: V(D)<V_% | D13: 4700 | E13: 10 | F13: 4700 | G13: 15
C14: V(D)<V_% | D14: 5000 | E14: 22
C15: V(D)<V_% | D15: 4000 | E15: 38
C16: V(D)<V_% | D16: 2600 | E16: 50 | F16: 2600 | G16: 55
C17: V(D)<V_% | D17: 3000 | E17: 57
C18: V(D)<V_% | D18: 2000 | E18: 85
C19: Dmedia | D19: 3500
B20: Sigma | C20: Dmax | D20: 5000
B21: Intestinos | C21: Dmax | D21: 4950 | F21: 5300
C22: V(D)<V_cc | D22: 4300 | E22: 15 | F22: 4300 | G22: 20
C23: V(D)<V_cc | D23: 3900 | E23: 100 | F23: 3900 | G23: 120
C24: V(D)<V_cc | D24: 3500 | E24: 130 | F24: 3500 | G24: 150
C25: V(D)<V_cc | D25: 2600 | E25: 150 | F25: 2600 | G25: 170
B26: Bulbo_Peneano | C26: V(D)<V_% | D26: 2200 | E26: 50
B27: Femur_I | C27: V(D)<V_% | D27: 3500 | E27: 5
C28: Dmax | D28: 4300 | F28: 4700
B29: Femur_D | C29: V(D)<V_% | D29: 3500 | E29: 5
C30: Dmax | D30: 4300 | F30: 4700
B31: Cauda_Equina | C31: Dmax | D31: 4000
A46: Si es necesario agregar mas lineas de constraints, revisar el codigo. Hardcodeado hasta este valor de fila. RL

Sheet PR 6000-20FX
A2: Prescripción: | B2: PR 6000-20FX | D2: =IF($B$2=RIGHT(CELL("filename",$B$2),LEN(CELL("filename",$B$2))-FIND("]",CELL("filename",$B$2))), "Todo OK ", "No coincide nombre del template con nombre de Prescripción") -> Todo OK
A4: Estructura | B4: Dosis total (cGy) | C4: Dosis diaria (cGy) | D4: Nro de fx | E4: Nro de etapa | G4: Protocolo Imágenes
A5: PTV_PR | B5: 6000 | C5: 300 | D5: ='PR 6000-20FX'!$B5/'PR 6000-20FX'!$C5 -> 20 | E5: 1 | G5: CBCT diario + CBCT primeros 3 días representativos para promedios
A7: Tipo de Estructura | B7: Estructura | C7: Tipo de Constraint | D7: Ideal | E7: Valor ref aux (dvh) | F7: Aceptable | G7: Valor ref limite aceptable aux (dvh)
A8: target | B8: PTV_PR | C8: V(D)>V_% | D8: 5880 | E8: 95
C9: Dmax | D9: 6420
B10: PTV_VS | C10: V(D)>V_% | D10: 5880 | E10: 95
C11: Dmax | D11: 6420
A12: oar | B12: Recto | C12: V(D)<V_% | D12: 6000 | E12: 1 | F12: 6000 | G12: 10
C13: V(D)<V_% | D13: 5000 | E13: 22
C14: V(D)<V_% | D14: 4000 | E14: 38
C15: V(D)<V_% | D15: 3000 | E15: 57
B16: Vejiga | C16: V(D)<V_% | D16: 6000 | E16: 3 | F16: 6000 | G16: 10
C17: V(D)<V_% | D17: 4800 | E17: 25
C18: V(D)<V_% | D18: 4000 | E18: 50
B19: Bulbo_Peneano | C19: V(D)<V_% | D19: 2200 | E19: 50
B20: Femur_I | C20: V(D)<V_% | D20: 3500 | E20: 5
C21: Dmax | D21: 3700
B22: Femur_D | C22: V(D)<V_% | D22: 3500 | E22: 5
C23: Dmax | D23: 3700
B24: Isquion | C24: V(D)<V_% | D24: 5700 | E24: 20
B25: Pene | C25: V(D)<V_cc | D25: 2600 | E25: 1
A46: Si es necesario agregar mas lineas de constraints, revisar el codigo. Hardcodeado hasta este valor de fila. RL

Sheet PR+VS 6000-20FX
A2: Prescripción: | B2: PR+VS 6000-20FX | D2: =IF($B$2=RIGHT(CELL("filename",$B$2),LEN(CELL("filename",$B$2))-FIND("]",CELL("filename",$B$2))), "Todo OK ", "No coincide nombre del template con nombre de Prescripción") -> Todo OK
A4: Estructura | B4: Dosis total (cGy) | C4: Dosis diaria (cGy) | D4: Nro de fx | E4: Nro de etapa | G4: Protocolo Imágenes
A5: PTV_PR | B5: 6000 | C5: 300 | D5: ='PR+VS 6000-20FX'!$B5/'PR+VS 6000-20FX'!$C5 -> 20 | E5: 1 | G5: CBCT diario + CBCT primeros 3 días representativos para promedios
A6: PTV_VS | B6: 6000 | C6: 300 | D6: ='PR+VS 6000-20FX'!$B6/'PR+VS 6000-20FX'!$C6 -> 20 | E6: 1
A8: Tipo de Estructura | B8: Estructura | C8: Tipo de Constraint | D8: Ideal | E8: Valor ref aux (dvh) | F8: Aceptable | G8: Valor ref limite aceptable aux (dvh)
A9: target | B9: PTV_PR | C9: V(D)>V_% | D9: 5880 | E9: 95
C10: Dmax | D10: 6420
B11: PTV_VS | C11: V(D)>V_% | D11: 5880 | E11: 95
C12: Dmax | D12: 6420
A13: oar | B13: Recto | C13: V(D)<V_% | D13: 6000 | E13: 1 | F13: 6000 | G13: 5
C14: V(D)<V_% | D14: 5000 | E14: 22
C15: V(D)<V_% | D15: 4000 | E15: 38
C16: V(D)<V_% | D16: 3000 | E16: 57
C17: V(D)<V_% | D17: 2000 | E17: 85
C18: Dmedia | D18: 3500
B19: Vejiga | C19: V(D)<V_% | D19: 6000 | E19: 3 | F19: 6000 | G19: 5
C20: V(D)<V_% | D20: 5680 | E20: 5
C21: V(D)<V_% | D21: 4800 | E21: 25
C22: V(D)<V_% | D22: 4000 | E22: 50
C23: Dmedia | D23: 4500
B24: Bulbo_Peneano | C24: V(D)<V_% | D24: 2200 | E24: 50
B25: Femur_I | C25: V(D)<V_% | D25: 3500 | E25: 5
B26: Femur_D | C26: V(D)<V_% | D26: 3500 | E26: 5
B27: Cauda_Equina | C27: Dmax | D27: 4000
B28: Intestinos | C28: Dmax | D28: 4600
C29: V(D)<V_cc | D29: 3700 | E29: 90
C30: V(D)<V_cc | D30: 3300 | E30: 130
B31: Sigma | C31: Dmax | D31: 5000
A46: Si es necesario agregar mas lineas de constraints, revisar el codigo. Hardcodeado hasta este valor de fila. RL

Sheet PR+VS+LN 6000-20FX
A2: Prescripción: | B2: PR+VS+LN 6000-20FX | D2: =IF($B$2=RIGHT(CELL("filename",$B$2),LEN(CELL("filename",$B$2))-FIND("]",CELL("filename",$B$2))), "Todo OK ", "No coincide nombre del template con nombre de Prescripción") -> Todo OK
A4: Estructura | B4: Dosis total (cGy) | C4: Dosis diaria (cGy) | D4: Nro de fx | E4: Nro de etapa | G4: Protocolo Imágenes
A5: PTV_PR | B5: 6000 | C5: 300 | D5: ='PR+VS+LN 6000-20FX'!$B5/'PR+VS+LN 6000-20FX'!$C5 -> 20 | E5: 1 | G5: CBCT diario + CBCT primeros 3 días representativos para promedios
A6: PTV_VS | B6: 6000 | C6: 300 | D6: ='PR+VS+LN 6000-20FX'!$B6/'PR+VS+LN 6000-20FX'!$C6 -> 20 | E6: 1
A7: PTV_LN | B7: 4400 | C7: 220 | D7: 20 | E7: 1
A9: Tipo de Estructura | B9: Estructura | C9: Tipo de Constraint | D9: Ideal | E9: Valor ref aux (dvh) | F9: Aceptable | G9: Valor ref limite aceptable aux (dvh)
A10: target | B10: PTV_PR | C10: V(D)>V_% | D10: 5880 | E10: 95 | F10: 5700 | G10: 95
C11: Dmax | D11: 6420
B12: PTV_VS | C12: V(D)>V_% | D12: 5880 | E12: 95 | F12: 5700 | G12: 95
C13: Dmax | D13: 6420
B14: PTV_LN | C14: V(D)>V_% | D14: 4268 | E14: 95 | F14: 4180 | G14: 95
A15: oar | B15: Recto | C15: V(D)<V_% | D15: 6000 | E15: 1 | F15: 6000 | G15: 3
C16: V(D)<V_% | D16: 5000 | E16: 22
C17: V(D)<V_% | D17: 4000 | E17: 38
C18: V(D)<V_% | D18: 3000 | E18: 57
C19: V(D)<V_% | D19: 2000 | E19: 85
C20: Dmedia | D20: 3500
B21: Vejiga | C21: V(D)<V_% | D21: 6000 | E21: 3 | F21: 6000 | G21: 5
C22: V(D)<V_% | D22: 5680 | E22: 5
C23: V(D)<V_% | D23: 4800 | E23: 25
C24: V(D)<V_% | D24: 4000 | E24: 50
C25: Dmedia | D25: 4500
B26: Bulbo_Peneano | C26: V(D)<V_% | D26: 2200 | E26: 50
B27: Femur_I | C27: V(D)<V_% | D27: 3500 | E27: 5
B28: Femur_D | C28: V(D)<V_% | D28: 3500 | E28: 5
B29: Cauda_Equina | C29: Dmax | D29: 4000
B30: Intestinos | C30: Dmax | D30: 4600
C31: V(D)<V_cc | D31: 3700 | E31: 90
C32: V(D)<V_cc | D32: 3300 | E32: 130
B33: Sigma | C33: Dmax | D33: 5000
A46: Si es necesario agregar mas lineas de constraints, revisar el codigo. Hardcodeado hasta este valor de fila. RL

Sheet PR+VS+LN 7020-27FX
A2: Prescripción: | B2: PR+VS+LN 7020-27FX | D2: =IF($B$2=RIGHT(CELL("filename",$B$2),LEN(CELL("filename",$B$2))-FIND("]",CELL("filename",$B$2))), "Todo OK ", "No coincide nombre del template con nombre de Prescripción") -> Todo OK
A4: Estructura | B4: Dosis total (cGy) | C4: Dosis diaria (cGy) | D4: Nro de fx | E4: Nro de etapa | G4: Protocolo Imágenes
A5: PTV_PR | B5: 7020 | C5: 260 | D5: ='PR+VS+LN 7020-27FX'!$B5/'PR+VS+LN 7020-27FX'!$C5 -> 27 | E5: 1 | G5: CBCT primeros 3 dias representativos para promedios + 1 por semana
A6: PTV_VS | B6: 7020 | C6: 260 | D6: ='PR+VS+LN 7020-27FX'!$B6/'PR+VS+LN 7020-27FX'!$C6 -> 27 | E6: 1
A7: PTV_LN | B7: 4860 | C7: 180 | D7: ='PR+VS+LN 7020-27FX'!$B7/'PR+VS+LN 7020-27FX'!$C7 -> 27 | E7: 1
A9: Tipo de Estructura | B9: Estructura | C9: Tipo de Constraint | D9: Ideal | E9: Valor ref aux (dvh) | F9: Aceptable | G9: Valor ref limite aceptable aux (dvh)
A10: target | B10: PTV_PR | C10: V(D)>V_% | D10: 6880 | E10: 95
C11: Dmax | D11: 7511
B12: PTV_VS | C12: V(D)>V_% | D12: 6880 | E12: 95
C13: Dmax | D13: 7511
B14: PTV_LN | C14: V(D)>V_% | D14: 4763 | E14: 95
A15: oar | B15: Recto | C15: V(D)<V_% | D15: 7000 | E15: 10 | F15: 7000 | G15: 20
C16: V(D)<V_% | D16: 6500 | E16: 25
C17: V(D)<V_% | D17: 6000 | E17: 35
C18: V(D)<V_% | D18: 5300 | E18: 35
C19: V(D)<V_% | D19: 4500 | E19: 50
C20: V(D)<V_% | D20: 4000 | E20: 40
B21: Vejiga | C21: V(D)<V_% | D21: 7000 | E21: 10 | F21: 7000 | G21: 20
C22: V(D)<V_% | D22: 6000 | E22: 30
C23: V(D)<V_% | D23: 4500 | E23: 50
B24: Intestinos | C24: V(D)<V_cc | D24: 5000 | E24: 1 | F24: 5000 | G24: 100
C25: V(D)<V_cc | D25: 4500 | E25: 150 | F25: 4500 | G25: 250
C26: V(D)<V_cc | D26: 4000 | E26: 350
C27: V(D)<V_cc | D27: 3900 | E27: 195
C28: V(D)<V_cc | D28: 3000 | E28: 500
B29: Bulbo_Peneano | C29: V(D)<V_% | D29: 4400 | E29: 50
C30: Dmedia | D30: 5000
B31: Femur_I | C31: V(D)<V_% | D31: 5000 | E31: 5 | F31: 5000 | G31: 10
B32: Femur_D | C32: V(D)<V_% | D32: 5000 | E32: 5 | F32: 5000 | G32: 10
B33: Pene | C33: V(D)<V_cc | D33: 3000 | E33: 1
B34: Cauda_Equina | C34: Dmax | D34: 5000
A46: Si es necesario agregar mas lineas de constraints, revisar el codigo. Hardcodeado hasta este valor de fila. RL

Sheet PR+VS+LN+LNpos 7020-27FX
A2: Prescripción: | B2: PR+VS+LN+LNpos 7020-27FX | D2: =IF($B$2=RIGHT(CELL("filename",$B$2),LEN(CELL("filename",$B$2))-FIND("]",CELL("filename",$B$2))), "Todo OK ", "No coincide nombre del template con nombre de Prescripción") -> Todo OK
A4: Estructura | B4: Dosis total (cGy) | C4: Dosis diaria (cGy) | D4: Nro de fx | E4: Nro de etapa | G4: Protocolo Imágenes
A5: PTV_PR | B5: 7020 | C5: 260 | D5: ='PR+VS+LN+LNpos 7020-27FX'!$B5/'PR+VS+LN+LNpos 7020-27FX'!$C5 -> 27 | E5: 1 | G5: CBCT primeros 3 dias representativos para promedios + 1 por semana
A6: PTV_VS | B6: 7020 | C6: 260 | D6: ='PR+VS+LN+LNpos 7020-27FX'!$B6/'PR+VS+LN+LNpos 7020-27FX'!$C6 -> 27 | E6: 1
A7: PTV_LNpos | B7: 5994 | C7: 222 | D7: ='PR+VS+LN+LNpos 7020-27FX'!$B7/'PR+VS+LN+LNpos 7020-27FX'!$C7 -> 27 | E7: 1
A8: PTV_LN | B8: 4860 | C8: 180 | D8: =B8/C8 -> 27 | E8: 1
A10: Tipo de Estructura | B10: Estructura | C10: Tipo de Constraint | D10: Ideal | E10: Valor ref aux (dvh) | F10: Aceptable | G10: Valor ref limite aceptable aux (dvh)
A11: target | B11: PTV_PR | C11: V(D)>V_% | D11: 6880 | E11: 95
C12: Dmax | D12: 7511
B13: PTV_VS | C13: V(D)>V_% | D13: 6880 | E13: 95
C14: Dmax | D14: 7511
B15: PTV_LNpos | C15: V(D)>V_% | D15: 5874 | E15: 95
B16: PTV_LN | C16: V(D)>V_% | D16: 4763 | E16: 95
A17: oar | B17: Recto | C17: V(D)<V_% | D17: 7000 | E17: 10 | F17: 7000 | G17: 20
C18: V(D)<V_% | D18: 6500 | E18: 25
C19: V(D)<V_% | D19: 6000 | E19: 35
C20: V(D)<V_% | D20: 4500 | E20: 50
B21: Vejiga | C21: V(D)<V_% | D21: 7000 | E21: 10 | F21: 7000 | G21: 20
C22: V(D)<V_% | D22: 6000 | E22: 30
C23: V(D)<V_% | D23: 4500 | E23: 50
B24: Intestinos | C24: V(D)<V_cc | D24: 5000 | E24: 1 | F24: 5000 | G24: 100
C25: V(D)<V_cc | D25: 4500 | E25: 150 | F25: 4500 | G25: 250
C26: V(D)<V_cc | D26: 4000 | E26: 350
C27: V(D)<V_cc | D27: 3000 | E27: 500
B28: Bulbo_Peneano | C28: V(D)<V_% | D28: 4400 | E28: 50
C29: Dmedia | D29: 5000
B30: Femur_I | C30: V(D)<V_% | D30: 5000 | E30: 5 | F30: 5000 | G30: 10
C31: Dmax | D31: 5200
B32: Femur_D | C32: V(D)<V_% | D32: 5000 | E32: 5 | F32: 5000 | G32: 10
C33: Dmax | D33: 5200
B34: Pene | C34: V(D)<V_cc | D34: 3000 | E34: 1
B35: Cauda_Equina | C35: Dmax | D35: 5000
